<?xml version="1.0" ?>
<sdf version="1.5">
    <model name="swerve_robot">
        <plugin name="hello_world" filename="libtest.dylib"/>

        <link name="swerve_body">
            <pose>0 0 0 1.5708 0 0</pose>
            <collision name="collision">
                <geometry>
                    <mesh><uri>model://swerve_robot/swerve_body.obj</uri></mesh>
                </geometry>
                <surface>
                    <contact>
                        <collide_bitmask>0x1</collide_bitmask>
                    </contact>
                    <friction>
                        <ode>
                            <mu>100</mu>
                            <mu2>50</mu2>
                        </ode>
                    </friction>
                </surface>
            </collision>
            <visual name="visual">
                <geometry>
                    <mesh><uri>model://swerve_robot/swerve_body.obj</uri></mesh>
                </geometry>
            </visual>
            <inertial>
                <mass>7</mass> <!-- kg -->
                <inertia>
                    <!-- 重心回りの慣性モーメント行列 -->
                    <ixx>0.14729166666</ixx>
                    <ixy>0</ixy>
                    <ixz>0</ixz>
                    <iyy>0.14729166666</iyy>
                    <iyz>0</iyz>
                    <izz>0.29166666666</izz>
                </inertia>
                <pose frame=''>0 0 0 0 -0 0</pose> <!-- 重心位置 -->
            </inertial>
        </link>

        <link name="lf_wheel">
            <pose>0.51 0.53 0 1.5708 0 0</pose>
            <collision name="collision">
                <geometry>
                    <mesh><uri>model://swerve_robot/swerve_wheel.obj</uri></mesh>
                </geometry>
                <surface>
                    <contact>
                        <collide_bitmask>0x2</collide_bitmask>
                    </contact>
                    <friction>
                        <ode>
                            <mu>100</mu>
                            <mu2>50</mu2>
                        </ode>
                    </friction>
                </surface>
            </collision>
            <visual name="visual">
                <geometry>
                    <mesh><uri>model://swerve_robot/swerve_wheel.obj</uri></mesh>
                </geometry>
            </visual>
            <!-- <inertial> -->
            <!--     <mass>0.5</mass> -->
            <!--     <inertia> -->
            <!--         <ixx>0.0005166666</ixx> -->
            <!--         <ixy>0</ixy> -->
            <!--         <ixz>0</ixz> -->
            <!--         <iyy>0.0005166666</iyy> -->
            <!--         <iyz>0</iyz> -->
            <!--         <izz>0.0009</izz> -->
            <!--     </inertia> -->
            <!-- </inertial> -->
        </link>

        <link name="rf_wheel">
            <pose>0.51 -0.50 0 1.5708 0 0</pose>
            <collision name="collision">
                <geometry>
                    <mesh><uri>model://swerve_robot/swerve_wheel.obj</uri></mesh>
                </geometry>
                <surface>
                    <contact>
                        <collide_bitmask>0x2</collide_bitmask>
                    </contact>
                    <friction>
                        <ode>
                            <mu>100</mu>
                            <mu2>50</mu2>
                        </ode>
                    </friction>
                </surface>
            </collision>
            <visual name="visual">
                <geometry>
                    <mesh><uri>model://swerve_robot/swerve_wheel.obj</uri></mesh>
                </geometry>
            </visual>
            <!-- <inertial> -->
            <!--     <mass>0.5</mass> -->
            <!--     <inertia> -->
            <!--         <ixx>0.0005166666</ixx> -->
            <!--         <ixy>0</ixy> -->
            <!--         <ixz>0</ixz> -->
            <!--         <iyy>0.0005166666</iyy> -->
            <!--         <iyz>0</iyz> -->
            <!--         <izz>0.0009</izz> -->
            <!--     </inertia> -->
            <!-- </inertial> -->
        </link>

        <link name="lb_wheel">
            <pose>-0.49 0.53 0 1.5708 0 0</pose>
            <collision name="collision">
                <geometry>
                    <mesh><uri>model://swerve_robot/swerve_wheel.obj</uri></mesh>
                </geometry>
                <surface>
                    <contact>
                        <collide_bitmask>0x2</collide_bitmask>
                    </contact>
                    <friction>
                        <ode>
                            <mu>100</mu>
                            <mu2>50</mu2>
                        </ode>
                    </friction>
                </surface>
            </collision>
            <visual name="visual">
                <geometry>
                    <mesh><uri>model://swerve_robot/swerve_wheel.obj</uri></mesh>
                </geometry>
            </visual>
            <!-- <inertial> -->
            <!--     <mass>0.5</mass> -->
            <!--     <inertia> -->
            <!--         <ixx>0.0005166666</ixx> -->
            <!--         <ixy>0</ixy> -->
            <!--         <ixz>0</ixz> -->
            <!--         <iyy>0.0005166666</iyy> -->
            <!--         <iyz>0</iyz> -->
            <!--         <izz>0.0009</izz> -->
            <!--     </inertia> -->
            <!-- </inertial> -->
        </link>

        <link name="rb_wheel">
            <pose>-0.49 -0.51 0 1.5708 0 0</pose>
            <collision name="collision">
                <geometry>
                    <mesh><uri>model://swerve_robot/swerve_wheel.obj</uri></mesh>
                </geometry>
                <surface>
                    <contact>
                        <collide_bitmask>0x2</collide_bitmask>
                    </contact>
                    <friction>
                        <ode>
                            <mu>100</mu>
                            <mu2>50</mu2>
                        </ode>
                    </friction>
                </surface>
            </collision>
            <visual name="visual">
                <geometry>
                    <mesh><uri>model://swerve_robot/swerve_wheel.obj</uri></mesh>
                </geometry>
            </visual>
            <!-- <inertial> -->
            <!--     <mass>0.5</mass> -->
            <!--     <inertia> -->
            <!--         <ixx>0.0005166666</ixx> -->
            <!--         <ixy>0</ixy> -->
            <!--         <ixz>0</ixz> -->
            <!--         <iyy>0.0005166666</iyy> -->
            <!--         <iyz>0</iyz> -->
            <!--         <izz>0.0009</izz> -->
            <!--     </inertia> -->
            <!-- </inertial> -->
        </link>

        <joint name="lf_wheel_joint" type="revolute2">
            <axis>
                <xyz>0 0 1</xyz>
            </axis>
            <axis2>
                <xyz>0 1 0</xyz>
            </axis2>
            <parent>swerve_body</parent>
            <child>lf_wheel</child>
        </joint>

        <joint name="rf_wheel_joint" type="revolute2">
            <axis>
                <xyz>0 0 1</xyz>
            </axis>
            <axis2>
                <xyz>0 1 0</xyz>
            </axis2>
            <parent>swerve_body</parent>
            <child>rf_wheel</child>
        </joint>

        <joint name="lb_wheel_joint" type="revolute2">
            <axis>
                <xyz>0 0 1</xyz>
            </axis>
            <axis2>
                <xyz>0 1 0</xyz>
            </axis2>
            <parent>swerve_body</parent>
            <child>lb_wheel</child>
        </joint>

        <joint name="rb_wheel_joint" type="revolute2">
            <axis>
                <xyz>0 0 1</xyz>
            </axis>
            <axis2>
                <xyz>0 1 0</xyz>
            </axis2>
            <parent>swerve_body</parent>
            <child>rb_wheel</child>
        </joint>


    </model>

</sdf>
